Workbook

Sheet Dashboard
A1: Weekly Progress Dashboard (Linked)
A3: Week Start Date | B3: =MIN(Daily_Log!A:A)
A4: Week End Date | B4: =MAX(Daily_Log!A:A)
A6: Completed Tasks | B6: =COUNTIF(Daily_Log!G:G,"☑") | C6: Total Tasks | D6: =COUNTIF(Daily_Log!G:G,"☐")+COUNTIF(Daily_Log!G:G,"☑") | E6: Completion Rate | F6: =IFERROR(B6/D6,0)
A9: Progress by Day (Daily_Log + DayN_Done)
A10: Day | B10: Completed | C10: Total | D10: Rate
A11: Day 1 | B11: =COUNTIFS(Daily_Log!B:B,"Day 1",Daily_Log!G:G,"☑") | C11: =COUNTIFS(Daily_Log!B:B,"Day 1",Daily_Log!G:G,"☐")+COUNTIFS(Daily_Log!B:B,"Day 1",Daily_Log!G:G,"☑") | D11: =IFERROR(B11/C11,0)
A12: Day 2 | B12: =COUNTIFS(Daily_Log!B:B,"Day 2",Daily_Log!G:G,"☑") | C12: =COUNTIFS(Daily_Log!B:B,"Day 2",Daily_Log!G:G,"☐")+COUNTIFS(Daily_Log!B:B,"Day 2",Daily_Log!G:G,"☑") | D12: =IFERROR(B12/C12,0)
A13: Day 3 | B13: =COUNTIFS(Daily_Log!B:B,"Day 3",Daily_Log!G:G,"☑") | C13: =COUNTIFS(Daily_Log!B:B,"Day 3",Daily_Log!G:G,"☐")+COUNTIFS(Daily_Log!B:B,"Day 3",Daily_Log!G:G,"☑") | D13: =IFERROR(B13/C13,0)
A14: Day 4 | B14: =COUNTIFS(Daily_Log!B:B,"Day 4",Daily_Log!G:G,"☑") | C14: =COUNTIFS(Daily_Log!B:B,"Day 4",Daily_Log!G:G,"☐")+COUNTIFS(Daily_Log!B:B,"Day 4",Daily_Log!G:G,"☑") | D14: =IFERROR(B14/C14,0)
A15: Day 5 | B15: =COUNTIFS(Daily_Log!B:B,"Day 5",Daily_Log!G:G,"☑") | C15: =COUNTIFS(Daily_Log!B:B,"Day 5",Daily_Log!G:G,"☐")+COUNTIFS(Daily_Log!B:B,"Day 5",Daily_Log!G:G,"☑") | D15: =IFERROR(B15/C15,0)
A16: Day 6 | B16: =COUNTIFS(Daily_Log!B:B,"Day 6",Daily_Log!G:G,"☑") | C16: =COUNTIFS(Daily_Log!B:B,"Day 6",Daily_Log!G:G,"☐")+COUNTIFS(Daily_Log!B:B,"Day 6",Daily_Log!G:G,"☑") | D16: =IFERROR(B16/C16,0)
A17: Day 7 | B17: =COUNTIFS(Daily_Log!B:B,"Day 7",Daily_Log!G:G,"☑") | C17: =COUNTIFS(Daily_Log!B:B,"Day 7",Daily_Log!G:G,"☐")+COUNTIFS(Daily_Log!B:B,"Day 7",Daily_Log!G:G,"☑") | D17: =IFERROR(B17/C17,0)
A19: Link Rule
A20: Dashboard counts tasks from Daily_Log only (☐/☑). Day1_Done~Day7_Done are evidence logs and are excluded from completion rate.

Sheet Daily_Log
A1: Daily Task Log (Day blocks auto-prebuilt for one week)
A3: Date | B3: Day | C3: Task ID | D3: Task | E3: Priority | F3: Owner | G3: Check | H3: Status | I3: Notes | J3: Done Time
A4: Day 1 - 2026-05-05
A5: 2026-05-05 | B5: Day 1 | C5: D1-01 | D5: Confirm app_list.xlsx has 14 target apps | E5: Medium | F5: William | G5: ☑ | H5: Done | I5: Config updated and validated | J5: 14:37
A6: 2026-05-05 | B6: Day 1 | C6: D1-02 | D6: Run 01_collect and verify outputs generated | E6: Medium | F6: William | G6: ☑ | H6: Done | I6: 01_collect completed (14/14 apps) | J6: 14:45
A7: 2026-05-05 | B7: Day 1 | C7: D1-03 | D7: Run 02_clean and verify outputs generated | E7: Medium | F7: William | G7: ☑ | H7: Done | I7: 02_clean completed | J7: 14:55
A8: 2026-05-05 | B8: Day 1 | C8: D1-04 | D8: Validate 14/14 app coverage and equal rows | E8: Medium | F8: William | G8: ☑ | H8: Done | I8: Day1 checks passed | J8: 15:15
A9: 2026-05-05 | B9: Day 1 | C9: D1-05 | D9: Record Day 1 log and key metrics | E9: Medium | F9: William | G9: ☑ | H9: Done | I9: Daily markdown log written | J9: 15:17
A10: 2026-05-05 | B10: Day 1 | C10: D1-06 | D10: Write daily summary and blockers | E10: Medium | F10: William | G10: ☑ | H10: Done | I10: Day 1 summary and blockers recorded | J10: 15:55
A11: Day 2 - 2026-05-06
A12: 2026-05-06 | B12: Day 2 | C12: D2-01 | D12: Build app-level base metrics table (avg/positive/low-star) | E12: Medium | F12: William | G12: ☑ | H12: Done | I12: app_base_metrics.csv + scripts/06_insights/build_app_base_metrics.py | J12: 20:32
A13: 2026-05-06 | B13: Day 2 | C13: D2-02 | D13: Compute Bayesian adjusted rating and confidence | E13: Medium | F13: William | G13: ☑ | H13: Done | I13: config/metrics.json + bayesian in build_health_score.py | J13: 20:32
A14: 2026-05-06 | B14: Day 2 | C14: D2-03 | D14: Implement momentum (period change or 8w slope) | E14: Medium | F14: William | G14: ☑ | H14: Done | I14: build_health_score.py momentum | J14: 20:32
A15: 2026-05-06 | B15: Day 2 | C15: D2-04 | D15: Calculate app health score table for 14 apps | E15: Medium | F15: William | G15: ☑ | H15: Done | I15: build_health_score.py | J15: 20:32
A16: 2026-05-06 | B16: Day 2 | C16: D2-05 | D16: Export app_health_score.csv and sanity-check ranking | E16: Medium | F16: William | G16: ☑ | H16: Done | I16: reports/tables/app_health_score.csv + verify OK | J16: 20:32
A17: 2026-05-06 | B17: Day 2 | C17: D2-06 | D17: Write Day 2 summary and blockers | E17: Medium | F17: William | G17: ☑ | H17: Done | I17: day2_2026-05-06.md | J17: 20:32
A18: Day 3 - 2026-05-07
A19: 2026-05-07 | B19: Day 3 | C19: D3-01 | D19: Create app-level benchmark outputs (BQ2) | E19: Medium | F19: William | G19: ☑ | H19: Done | I19: reports/tables/app_benchmark_bq2.csv | J19: 20:48
A20: 2026-05-07 | B20: Day 3 | C20: D3-02 | D20: Create publisher-level benchmark outputs | E20: Medium | F20: William | G20: ☑ | H20: Done | I20: reports/tables/publisher_benchmark.csv | J20: 20:48
A21: 2026-05-07 | B21: Day 3 | C21: D3-03 | D21: Create flagship 7-app benchmark view | E21: Medium | F21: William | G21: ☑ | H21: Done | I21: reports/tables/flagship_7_benchmark.csv | J21: 20:48
A22: 2026-05-07 | B22: Day 3 | C22: D3-04 | D22: Build volume vs rating scatter source table | E22: Medium | F22: William | G22: ☑ | H22: Done | I22: reports/tables/volume_vs_rating_scatter.csv | J22: 20:48
A23: 2026-05-07 | B23: Day 3 | C23: D3-05 | D23: Draft Page 2 competitor findings bullets | E23: Medium | F23: William | G23: ☑ | H23: Done | I23: reports/page2_competitor_findings_draft.md | J23: 20:48
A24: 2026-05-07 | B24: Day 3 | C24: D3-06 | D24: Write Day 3 summary and blockers | E24: Medium | F24: William | G24: ☑ | H24: Done | I24: day3_2026-05-07.md + tracker | J24: 20:48
A25: Day 4 - 2026-05-27
A26: 2026-05-27 | B26: Day 4 | C26: D4-01 | D26: Create themes.yml v1 dictionary | E26: Medium | F26: William | G26: ☑ | H26: Done | I26: themes.yml v2 (18 themes, 13 neg + 5 pos, exclude rules) | J26: 19:30
A27: 2026-05-27 | B27: Day 4 | C27: D4-02 | D27: Run rule-based multi-label theme tagging | E27: Medium | F27: William | G27: ☑ | H27: Done | I27: scripts/06_insights/build_review_themes.py | J27: 19:32
A28: 2026-05-27 | B28: Day 4 | C28: D4-03 | D28: Export reviews_with_themes dataset | E28: Medium | F28: William | G28: ☑ | H28: Done | I28: reviews_with_themes.csv (10940 rows; coverage 45.2%) | J28: 19:32
A29: 2026-05-27 | B29: Day 4 | C29: D4-04 | D29: Compute low-star and positive theme rankings | E29: Medium | F29: William | G29: ☑ | H29: Done | I29: theme_summary_overall/by_app + low_star_theme_summary | J29: 19:33
A30: 2026-05-27 | B30: Day 4 | C30: D4-05 | D30: Run quick manual QA on theme hits and refine once | E30: Medium | F30: William | G30: ☑ | H30: Done | I30: v1→v2: Fun FP 462→382; Difficulty 29→113; Account→3 | J30: 19:35
A31: 2026-05-27 | B31: Day 4 | C31: D4-06 | D31: Write Day 4 summary and blockers | E31: Medium | F31: William | G31: ☑ | H31: Done | I31: docs/daily_logs/day4_2026-05-27.md | J31: 19:40
A32: 2026-05-27 | B32: Day 4 | C32: D4-07 | D32: Manual theme validation sample review | E32: High | F32: William | G32: ☒ | H32: Cancelled | I32: v1→v2 self-check already shipped on Day 4; second manual pass deferred to Phase 2 (LLM-assisted) | J32: -
A33: Day 5 - 2026-05-27
A34: 2026-05-27 | B34: Day 5 | C34: D5-01 | D34: Compute Frequency/Impact/Severity by theme | E34: Medium | F34: William | G34: ☑ | H34: Done | I34: frequency/impact/severity from theme_summary_overall.csv | J34: 21:20
A35: 2026-05-27 | B35: Day 5 | C35: D5-02 | D35: Calculate Priority Score and map P0-P3 | E35: Medium | F35: William | G35: ☑ | H35: Done | I35: priority score + P0-P3 from quantile buckets + critical flag | J35: 21:20
A36: 2026-05-27 | B36: Day 5 | C36: D5-03 | D36: Build recommendation_matrix table | E36: Medium | F36: William | G36: ☑ | H36: Done | I36: reports/tables/recommendation_matrix.csv | J36: 21:21
A37: 2026-05-27 | B37: Day 5 | C37: D5-04 | D37: Draft BQ5 product recommendations | E37: Medium | F37: William | G37: ☑ | H37: Done | I37: day5_2026-05-27.md business recommendations section | J37: 21:22
A38: 2026-05-27 | B38: Day 5 | C38: D5-05 | D38: Prepare Page 4 recommendation source data | E38: Medium | F38: William | G38: ☑ | H38: Done | I38: theme_priority_score.csv + theme_priority_by_app.csv | J38: 21:21
A39: 2026-05-27 | B39: Day 5 | C39: D5-06 | D39: Write Day 5 summary and blockers | E39: Medium | F39: William | G39: ☑ | H39: Done | I39: docs/daily_logs/day5_2026-05-27.md | J39: 21:22
A40: 2026-05-27 | B40: Day 5 | C40: D5-07 | D40: Prepare Power BI source tables and relationship plan | E40: High | F40: William | G40: ☑ | H40: Done | I40: Power BI source tables + relationship note generated | J40: 21:23
A41: Day 6 - 2026-05-28
...

Sheet Day1_Done
A1: Day 1 Completion Log
A3: Date | B3: 2026-05-05 | D3: Owner | E3: William
A5: Section | B5: Metric | C5: Value | D5: Status | E5: Evidence/File | F5: Notes
A6: Run | B6: Pipeline step executed | C6: 01_collect + 02_clean | D6: Done | E6: scripts/01_collect, scripts/02_clean
A7: Run | B7: Run time | C7: 2026-05-05 14:55:58 | D7: Done | E7: reports/quality_report.csv
A8: Validation | B8: raw_rows | C8: 16800 | D8: Done | E8: data/raw/google_play_reviews_raw.csv
A9: Validation | B9: clean_all_rows | C9: 15290 | D9: Done | E9: data/processed/clean_all_languages.csv
A10: Validation | B10: clean_en_rows | C10: 10956 | D10: Done | E10: data/processed/clean_en_only.csv
A11: Validation | B11: english_share | C11: 0.6521 | D11: Done | E11: calc: clean_en/raw
A12: Validation | B12: date_min | C12: 2024-02-12 00:12:16 | D12: Done | E12: raw at
A13: Validation | B13: date_max | C13: 2026-05-04 14:37:17 | D13: Done | E13: raw at
A14: Quality | B14: Key quality metric #1 | C14: duplicate_rate=0.0 | D14: Done | E14: reports/quality_report.csv
A15: Quality | B15: Key quality metric #2 | C15: empty_text_rate=0.0001 | D15: Done | E15: reports/quality_report.csv
A16: Output | B16: Primary output file #1 | C16: google_play_reviews_raw.csv | D16: Done | E16: data/raw/
A17: Output | B17: Primary output file #2 | C17: quality_report.csv | D17: Done | E17: reports/
A18: Summary | B18: Day conclusion | C18: Day 1 checks passed; ready for Day 2 | D18: Done | E18: docs/daily_logs/day1_2026-05-05.md

Sheet Day2_Done
A1: Day 2 Completion Log
A3: Date | D3: Owner | E3: William
A5: Section | B5: Metric | C5: Value | D5: Status | E5: Evidence/File | F5: Notes
A6: Metrics | B6: avg_rating_by_app | C6: see app_base_metrics | D6: Done | E6: reports/tables/app_base_metrics.csv
A7: Metrics | B7: positive_share_by_app | C7: computed | D7: Done | E7: app_base_metrics.csv
A8: Metrics | B8: low_star_share_by_app | C8: computed | D8: Done | E8: app_base_metrics.csv
A9: Metrics | B9: bayesian_adjusted_rating | C9: global_mean 3.676 | D9: Done | E9: app_health_score.csv
A10: Metrics | B10: confidence | C10: all 1.0 (n≥513) | D10: Done | E10: app_health_score.csv
A11: Metrics | B11: momentum | C11: weekly slope / fallback | D11: Done | E11: app_health_score.csv
A12: Output | B12: app_health_score.csv | C12: 14 rows | D12: Done | E12: reports/tables/app_health_score.csv
A13: Validation | B13: ranking_sanity_check | C13: VERIFICATION OK + rank review | D13: Done | E13: verify script / manual
A14: Summary | B14: day_conclusion | C14: day2_2026-05-06.md | D14: Done | E14: docs/daily_logs/

Sheet Day3_Done
A1: Day 3 Completion Log
A3: Date | D3: Owner | E3: William
A5: Section | B5: Metric | C5: Value | D5: Status | E5: Evidence/File | F5: Notes
A6: Output | B6: app_benchmark_bq2.csv | C6: 14 apps | D6: Done | E6: reports/tables/app_benchmark_bq2.csv
A7: Output | B7: publisher_benchmark.csv | C7: 8 publishers | D7: Done | E7: reports/tables/publisher_benchmark.csv
A8: Output | B8: flagship_7_benchmark.csv | C8: 7 apps | D8: Done | E8: reports/tables/flagship_7_benchmark.csv
A9: Output | B9: volume_vs_rating_scatter.csv | C9: 14 apps | D9: Done | E9: reports/tables/volume_vs_rating_scatter.csv
A10: Validation | B10: benchmark_consistency_check | C10: merged from base+health | D10: Done | E10: same grain as Day 2 tables
A11: Summary | B11: day_conclusion | C11: day3 log + Page2 draft | D11: Done | E11: docs/daily_logs/day3_2026-05-07.md

Sheet Day4_Done
A1: Day 4 Completion Log
A3: Date | B3: 2026-05-27 | D3: Owner | E3: William
A5: Section | B5: Metric | C5: Value | D5: Status | E5: Evidence/File | F5: Notes
A6: Config | B6: themes.yml_created | C6: 18 themes (13 neg + 5 pos), v2 with exclude rules | D6: Done | E6: config/themes.yml
A7: Output | B7: reviews_with_themes.csv | C7: 10940 rows, multi-label | D7: Done | E7: data/processed/reviews_with_themes.csv
A8: Metrics | B8: theme_coverage_rate | C8: 45.2% (≥1 theme) | D8: Done | E8: reports/tables/theme_summary_overall.csv
A9: Metrics | B9: low_star_theme_topN | C9: Fun 12.2%; Crash 8.1%; Loading 5.7%; Pay-to-win 3.9%; Difficulty 3.6% | D9: Done | E9: reports/tables/low_star_theme_summary.csv
A10: Metrics | B10: positive_theme_topN | C10: Fun n=3567 share=32.6%; Story n=519; Visual n=239; Social n=230 | D10: Done | E10: reports/tables/theme_summary_overall.csv
A11: Validation | B11: manual_theme_QA_round1 | C11: v1→v2 self-check done; D4-07 cancelled, second pass deferred to Phase 2 | D11: Cancelled | E11: reports/tables/theme_validation_sample.csv
A12: Summary | B12: day_conclusion | C12: Theme pipeline shipped; Crash rating_gap +1.28; Loading +1.08 → Day 5 Priority | D12: Done | E12: docs/daily_logs/day4_2026-05-27.md
A13: Task ID | B13: D4-07 | D13: Todo
A14: Task Name | B14: Manual theme validation sample review
A15: Description | B15: Manually review a sample of 100 low-star reviews and 50 high-star reviews to check false positives, false negatives, missing keywords, and obvious misclassification cases in the rule-based theme tagging.
A16: Expected Output / Evidence | B16: docs/theme_validation_notes.md; Updated config/themes.yml if keywords or exclude_keywords are refined
A17: Purpose | B17: Supports Theme Taxonomy and makes rule-based classification more defensible for DA/BA interview discussion.

Sheet Day5_Done
A1: Day 5 Completion Log
A3: Date | B3: 2026-05-27 | D3: Owner | E3: William
A5: Section | B5: Metric | C5: Value | D5: Status | E5: Evidence/File | F5: Notes
A6: Metrics | B6: frequency | C6: theme_share (global) / theme_share_in_app (app-level) | D6: Done | E6: reports/tables/theme_priority_score.csv
A7: Metrics | B7: impact | C7: max(rating_gap, 0) for negative themes | D7: Done | E7: reports/tables/theme_priority_score.csv
A8: Metrics | B8: severity | C8: share_low_1_2 | D8: Done | E8: reports/tables/theme_priority_score.csv
A9: Metrics | B9: priority_score | C9: norm(freq)×norm(impact)×norm(severity)×1.5^critical | D9: Done | E9: reports/tables/theme_priority_score.csv
A10: Output | B10: recommendation_matrix.csv | C10: 8 rows (P0+P1), owner/action/30-day-goal included | D10: Done | E10: reports/tables/recommendation_matrix.csv
A11: Output | B11: P0_P1_P2_P3_table | C11: theme_priority_score.csv with priority_bucket | D11: Done | E11: reports/tables/theme_priority_score.csv
A12: Summary | B12: day_conclusion | C12: Day 5 BQ5 delivered; backlog priorities ready for Page 4 | D12: Done | E12: docs/daily_logs/day5_2026-05-27.md
A13: Task ID | B13: D5-07 | D13: Todo
A14: Task Name | B14: Prepare Power BI source tables and relationship plan
A15: Description | B15: Confirm all dashboard-ready tables are exported and named consistently before Power BI build; prepare relationship plan for app-level, publisher-level, theme-level, and recommendation-level tables.
A16: Expected Output / Evidence | B16: reports/tables/app_summary.csv; reports/tables/publisher_summary.csv; reports/tables/health_score.csv; reports/tables/theme_summary.csv; reports/tables/low_star_theme_summary.csv; reports/tables/positive_theme_summary.csv; reports/tables/app_theme_matrix.csv; reports/tables/recommendation_matrix.csv; docs/powerbi_data_model_notes.md
A17: Purpose | B17: Reduces Day 6 workload and avoids dashboard blocking due to messy source tables.

Sheet Day6_Done
A1: Day 6 Completion Log
A3: Date | B3: 2026-05-28 | D3: Owner | E3: William
A5: Section | B5: Metric | C5: Value | D5: Status | E5: Evidence/File | F5: Notes
A6: Dashboard | B6: page1_executive | C6: Tableau Page 1 complete (Executive Overview). | D6: Done | E6: reports/每日复盘/Mobile_Game_Satisfaction_Tableau.twbx | F6: dashboard_page1.png captured
A7: Dashboard | B7: page2_competitor | C7: Tableau Page 2 complete (Competitor Benchmark). | D7: Done | E7: reports/每日复盘/Mobile_Game_Satisfaction_Tableau.twbx | F7: dashboard_page2.png captured
A8: Dashboard | B8: page3_themes | C8: Tableau Page 3 complete (Theme Insights). | D8: Done | E8: reports/每日复盘/Mobile_Game_Satisfaction_Tableau.twbx | F8: dashboard_page3.png captured
A9: Dashboard | B9: page4_recommendation | C9: Tableau Page 4 complete (Product Recommendation). | D9: Done | E9: reports/每日复盘/Mobile_Game_Satisfaction_Tableau.twbx | F9: dashboard_page4.png captured
A10: Report | B10: insight_report_v1 | C10: Bilingual 9 sections; 8 embedded figures; ~1.4 MB PDF | D10: Done | E10: reports/每日复盘/User_Satisfaction_Insight_Report.pdf
A11: Validation | B11: visual_QA | C11: All 8 PNGs regenerated from CSV; visual sanity check OK | D11: Done | E11: reports/每日复盘/figures/
A12: Summary | B12: day_conclusion | C12: Day 6 dashboard + report deliverables complete; Tableau build finished on macOS. | D12: Done | E12: docs/daily_logs/day6_2026-05-28.md
A13: Task ID | B13: D6-07 | D13: Done
A14: Task Name | B14: Add Data Honesty & Limitations section to insight report
A15: Description | B15: Add a short limitations section: Google Play reviews are public samples (not full user population); metrics are review-based proxy signals; no internal retention/conversion/revenue/DAU or causal impact analysis.
A16: Expected Output / Evidence | B16: Limitations section in reports/Mobile_Game_Review_Analytics_Insight_Report.docx; same limitation note summarized in README
A17: Purpose | B17: Aligns with design doc and prevents overclaiming business impact.

Sheet Day7_Done
A1: Day 7 Completion Log
A3: Date | D3: Owner | E3: William
A5: Section | B5: Metric | C5: Value | D5: Status | E5: Evidence/File | F5: Notes
A6: Portfolio | B6: README_update | D6: Todo
A7: Portfolio | B7: dashboard_screenshots | D7: Todo
A8: Career | B8: resume_bullets | D8: Todo
A9: Career | B9: interview_storyline | D9: Todo
A10: QA | B10: final_package_QA | D10: Todo
A11: Output | B11: deliverable_freeze | D11: Todo
A12: Summary | B12: day_conclusion | D12: Todo
A13: Task ID | B13: D7-07 | D13: Todo
A14: Task Name | B14: Freeze public portfolio version and clean placeholders
A15: Description | B15: Remove temporary placeholders, verify file paths, check dashboard screenshots, ensure README/report wording is professional, and create clean public-facing package.
A16: Expected Output / Evidence | B16: portfolio/Project_README.md; portfolio/Dashboard_Screenshots.pdf; portfolio/Insight_Report.pdf; portfolio/Methodology_Appendix.pdf; private_job_prep/Resume_Bullets.docx; private_job_prep/Interview_Story.docx
A17: Purpose | B17: Separates public portfolio materials from private job-prep materials.
